<mujoco>
	<option gravity = "0 0 -9.81"/>
	<worldbody>
        <light diffuse=".8 .8 .8" pos="0 0 5" dir="0 0 -1"/>
		<geom type="plane" size="5 5 0.1" rgba=".9 .9 .9 1"/>
		<body name="chassis" pos="0 0 0.2" euler="0 90 0">
			<joint type="free"/>
			<geom type="box" size=".3 .2 .6" rgba=".9 .9 0 0.6"/>
			<site name="marker" pos="0 0 0" size="0.1"/>
			<body pos="0.2 0 .5" euler="90 0 0">
				<joint name="front_left_wheel" type="hinge" axis="0 0 -1"/>
				<geom type="cylinder" size=".2 .20" rgba="0 .9 0 1"/>
			</body>
			<body pos="0.2 0 -0.5" euler="90 0 0">
				<joint name="front_right_wheel" type="hinge" axis="0 0 -1"/>
				<geom type="cylinder" size=".2 .20" rgba="0 .9 0 1"/>
			</body>
			<body name="child_body" pos="-0.6 0 0">
				<joint name="my_pin_joint" type="hinge" pos="0.6 0 0" axis="0.1 1 0.1"/>
				<!-- <geom type="box" size="0.8 0.1 0.2" contype="0" conaffinity="0"/> -->
				<geom type="box" size="0.8 0.05 0.10" contype="0" conaffinity="0"/>
			</body>
		</body>
	</worldbody>
	<sensor>
		<framepos objtype="site" objname="marker"/>
	</sensor>
	<actuator>
		<motor name="front_left_force_servo" joint="front_left_wheel" forcerange="-100 100"/>
		<motor name="front_right_force_servo" joint="front_right_wheel" forcerange="-100 100"/>
	</actuator>
</mujoco> 