<mujoco>
	<option gravity = "0 0 -9.81"/>
	<worldbody>
        <light diffuse=".5 .5 .5" pos="0 0 3" dir="0 0 -1"/>
		<geom type="plane" size="5 5 0.1" rgba=".9 .9 .9 1"/>
		<body name="chassis" pos="0 0 0.2" euler="0 90 0">
			<joint type="free"/>
			<geom type="box" size=".05 .2 .6" rgba=".9 .9 0 1"/>
			<site name="marker" pos="0 0 0" size="0.1"/>
			<body pos="0 .3 -.5" euler="90 0 0">
				<joint name="back_left_wheel" type="hinge" axis="0 0 -1"/>
				<geom type="cylinder" size=".2 .05" rgba="0 .9 0 1"/>
			</body>
			<body pos="0 -.3 -.5" euler="90 0 0">
				<joint name="back_right_wheel" type="hinge" axis="0 0 -1"/>
				<geom type="cylinder" size=".2 .05" rgba="0 .9 0 1"/>
			</body>

			<body pos="0 .3 .5" euler="90 0 0">
				<joint name="front_left_wheel" type="hinge" axis="0 0 -1"/>
				<geom type="cylinder" size=".2 .05" rgba="0 .9 0 1"/>
			</body>
			<body pos="0 -.3 .5" euler="90 0 0">
				<joint name="front_right_wheel" type="hinge" axis="0 0 -1"/>
				<geom type="cylinder" size=".2 .05" rgba="0 .9 0 1"/>
			</body>
		</body>
	</worldbody>
	<sensor>
		<framepos objtype="site" objname="marker"/>
	</sensor>
	<actuator>
		<velocity name="front_left_velocity_servo" joint="front_left_wheel" kv="200"/>
		<velocity name="front_right_velocity_servo" joint="front_right_wheel" kv="200"/>
		<velocity name="back_left_velocity_servo" joint="back_left_wheel" kv="200"/>
		<velocity name="back_right_velocity_servo" joint="back_right_wheel" kv="200"/>
	</actuator>
</mujoco> 